Workbook

Sheet Integrated ROM
A1: Phase | B1: Task | C1: Scope / Description | D1: Totals | E1: Dev 1 - Frontend | F1: Dev 2 - Backend | G1: Dev 3 - Design | H1: Dev 3 - .NET | I1: Dev 4 - Testing | J1: PM | K1: CM | L1: PD
A2: Mobilisation | B2: Initiation and Scope Confirmation | C2: Confirm objectives, production scope, stakeholders, constraints and acceptance approach. | D2: =SUM(E2:L2) | E2: 8 | F2: 8 | G2: 4 | H2: 0 | I2: 0 | J2: 60 | K2: 0 | L2: 0
A3: Mobilisation | B3: Project Governance and Planning | C3: Delivery governance, reporting, RAID management, scheduling and commercial coordination. | D3: =SUM(E3:L3) | E3: 0 | F3: 0 | G3: 0 | H3: 0 | I3: 0 | J3: 40 | K3: 0 | L3: 40
A4: Mobilisation | B4: Requirements Gathering / Targeted Workshops | C4: Validate tool scope, user journeys, data, symbols, access rules and non-functional requirements. | D4: =SUM(E4:L4) | E4: 8 | F4: 8 | G4: 24 | H4: 0 | I4: 0 | J4: 24 | K4: 0 | L4: 16
A5: Foundation | B5: Backend spatial API | C5: Productionise FastAPI/PostGIS spatial services, contracts, validation, paging and shared geospatial operations. | D5: =SUM(E5:L5) | E5: 16 | F5: 160 | G5: 8 | H5: 0 | I5: 0 | J5: 16 | K5: 0 | L5: 0
A6: Foundation | B6: Frontend web application base | C6: Production React/OpenLayers application shell, routing, state, error handling and shared components. | D6: =SUM(E6:L6) | E6: 80 | F6: 0 | G6: 0 | H6: 0 | I6: 0 | J6: 0 | K6: 0 | L6: 0
A7: Foundation | B7: UI | C7: Design system, responsive layouts, ribbon framework, panels, accessibility and consistent interaction patterns. | D7: =SUM(E7:L7) | E7: 20 | F7: 20 | G7: 80 | H7: 0 | I7: 0 | J7: 16 | K7: 0 | L7: 0
A8: Application Tools | B8: Search | C8: Ribbon / contextual tool group
A9: Search | B9: Universal search box | C9: Search addresses, parcels/SPI, localities and configured datasets; autocomplete, keyboard submission, result categories, map navigation and error handling. | D9: =SUM(E9:L9) | E9: 48 | F9: 80 | G9: 16 | H9: 0 | I9: 16 | J9: 0 | K9: 0 | L9: 0
A10: Application Tools | B10: Search subtotal | D10: =SUM(D9:D9) | E10: =SUM(E9:E9) | F10: =SUM(F9:F9) | G10: =SUM(G9:G9) | H10: =SUM(H9:H9) | I10: =SUM(I9:I9) | J10: =SUM(J9:J9) | K10: =SUM(K9:K9) | L10: =SUM(L9:L9)
A11: Application Tools | B11: Home Tab | C11: Ribbon / contextual tool group
A12: Home Tab | B12: Open project | C12: Load a saved map session containing layers, extent, filters, drawings and other supported state. | D12: =SUM(E12:L12) | E12: 16 | F12: 16 | G12: 4 | H12: 0 | I12: 4 | J12: 0 | K12: 0 | L12: 0
A13: Home Tab | B13: Save project | C13: Persist the current map session for the authenticated user. | D13: =SUM(E13:L13) | E13: 16 | F13: 24 | G13: 4 | H13: 0 | I13: 4 | J13: 0 | K13: 0 | L13: 0
A14: Home Tab | B14: Save project as | C14: Copy an existing project under a new name. | D14: =SUM(E14:L14) | E14: 8 | F14: 4 | G14: 0 | H14: 0 | I14: 4 | J14: 0 | K14: 0 | L14: 0
A15: Home Tab | B15: Initial View | C15: Return the map to its configured startup extent and state. | D15: =SUM(E15:L15) | E15: 4 | F15: 0 | G15: 0 | H15: 0 | I15: 4 | J15: 0 | K15: 0 | L15: 0
A16: Home Tab | B16: Home panel | C16: Welcome content, application description, release information and useful links. | D16: =SUM(E16:L16) | E16: 8 | F16: 0 | G16: 4 | H16: 0 | I16: 4 | J16: 0 | K16: 0 | L16: 0
A17: Home Tab | B17: Previous Extent | C17: Navigate backwards through map extent history. | D17: =SUM(E17:L17) | E17: 12 | F17: 0 | G17: 0 | H17: 0 | I17: 4 | J17: 0 | K17: 0 | L17: 0
A18: Home Tab | B18: Next Extent | C18: Navigate forwards through map extent history. | D18: =SUM(E18:L18) | E18: 4 | F18: 0 | G18: 0 | H18: 0 | I18: 4 | J18: 0 | K18: 0 | L18: 0
A19: Home Tab | B19: Zoom to XY | C19: Navigate using latitude/longitude, Vicgrid, MGA and supported coordinate formats. | D19: =SUM(E19:L19) | E19: 12 | F19: 4 | G19: 4 | H19: 0 | I19: 4 | J19: 0 | K19: 0 | L19: 0
A20: Home Tab | B20: Zones ON/OFF | C20: Efficiently toggle all configured planning-zone layers. | D20: =SUM(E20:L20) | E20: 8 | F20: 4 | G20: 0 | H20: 0 | I20: 4 | J20: 0 | K20: 0 | L20: 0
A21: Home Tab | B21: Overlays ON/OFF | C21: Efficiently toggle all configured planning-overlay layers. | D21: =SUM(E21:L21) | E21: 8 | F21: 4 | G21: 0 | H21: 0 | I21: 4 | J21: 0 | K21: 0 | L21: 0
A22: Home Tab | B22: Identify launcher | C22: Home-tab entry point into the shared Identify tool. | D22: =SUM(E22:L22) | E22: 4 | F22: 0 | G22: 0 | H22: 0 | I22: 4 | J22: 0 | K22: 0 | L22: 0
A23: Home Tab | B23: Google Street View | C23: Launch and synchronise Street View position and direction with the map. | D23: =SUM(E23:L23) | E23: 32 | F23: 16 | G23: 8 | H23: 0 | I23: 8 | J23: 0 | K23: 0 | L23: 0
... A33: Home Tab | B33: Help Videos | C33: Contextual links or embedded videos for important workflows. | D33: =SUM(E33:L33) | E33: 4 | F33: 0 | G33: 4 | H33: 0 | I33: 0 | J33: 0 | K33: 0 | L33: 0
A34: Application Tools | B34: Home Tab subtotal | D34: =SUM(D12:D33) | E34: =SUM(E12:E33) | F34: =SUM(F12:F33) | G34: =SUM(G12:G33) | H34: =SUM(H12:H33) | I34: =SUM(I12:I33) | J34: =SUM(J12:J33) | K34: =SUM(K12:K33) | L34: =SUM(L12:L33)
A35: Application Tools | B35: Map Tab | C35: Ribbon / contextual tool group
A36: Map Tab | B36: Layer Catalogue | C36: Search, browse and add authorised datasets using catalogue metadata and categories. | D36: =SUM(E36:L36) | E36: 40 | F36: 40 | G36: 16 | H36: 0 | I36: 8 | J36: 0 | K36: 0 | L36: 0
A37: Map Tab | B37: Layer List | C37: Groups, ordering, visibility, opacity, legend, scale restrictions and layer actions. | D37: =SUM(E37:L37) | E37: 64 | F37: 16 | G37: 16 | H37: 0 | I37: 16 | J37: 0 | K37: 0 | L37: 0
A38: Map Tab | B38: Time Slider | C38: Discover time-enabled layers and filter one or more layers by date, range or period. | D38: =SUM(E38:L38) | E38: 48 | F38: 32 | G38: 8 | H38: 0 | I38: 16 | J38: 0 | K38: 0 | L38: 0
A39: Map Tab | B39: Identify with options | C39: Point, rectangle, polygon and freehand identify; selectable layers, buffer and add/subtract result modes. | D39: =SUM(E39:L39) | E39: 48 | F39: 40 | G39: 8 | H39: 0 | I39: 16 | J39: 0 | K39: 0 | L39: 0
A40: Map Tab | B40: Query | C40: Visual attribute query builder with conditions, validation, paging and result actions. | D40: =SUM(E40:L40) | E40: 40 | F40: 40 | G40: 8 | H40: 0 | I40: 8 | J40: 0 | K40: 0 | L40: 0
A41: Map Tab | B41: Zone Intersect | C41: Intersect a property or drawing with planning zones and summarise area by zone. | D41: =SUM(E41:L41) | E41: 24 | F41: 32 | G41: 0 | H41: 0 | I41: 8 | J41: 0 | K41: 0 | L41: 0
A42: Map Tab | B42: Overlay Intersect | C42: Intersect a property or drawing with planning overlays and summarise area by overlay. | D42: =SUM(E42:L42) | E42: 24 | F42: 32 | G42: 0 | H42: 0 | I42: 8 | J42: 0 | K42: 0 | L42: 0
A43: Map Tab | B43: Amendment Search | C43: Planning scheme and amendment autocomplete, status/type criteria and map navigation. | D43: =SUM(E43:L43) | E43: 24 | F43: 32 | G43: 0 | H43: 0 | I43: 8 | J43: 0 | K43: 0 | L43: 0
A44: Map Tab | B44: Heritage Overlay Search | C44: Search by LGA and heritage-overlay number, activate the layer and zoom to results. | D44: =SUM(E44:L44) | E44: 24 | F44: 24 | G44: 0 | H44: 0 | I44: 8 | J44: 0 | K44: 0 | L44: 0
A45: Map Tab | B45: Generic Layer Filter | C45: Create and apply attribute conditions that restrict the displayed features of a layer. | D45: =SUM(E45:L45) | E45: 24 | F45: 32 | G45: 0 | H45: 0 | I45: 8 | J45: 0 | K45: 0 | L45: 0
A46: Map Tab | B46: Filter Overlays | C46: Filter overlay layers by schedule or subtype, such as ESO1. | D46: =SUM(E46:L46) | E46: 24 | F46: 16 | G46: 0 | H46: 0 | I46: 8 | J46: 0 | K46: 0 | L46: 0
A47: Map Tab | B47: Filter Zones | C47: Filter zone layers by schedule or subtype, such as LDRZ1. | D47: =SUM(E47:L47) | E47: 24 | F47: 16 | G47: 0 | H47: 0 | I47: 8 | J47: 0 | K47: 0 | L47: 0
... A49: Map Tab | B49: Upload Data | C49: Validate and load CSV, XLSX, KML, GeoJSON and zipped Shapefile data into the user session. | D49: =SUM(E49:L49) | E49: 40 | F49: 64 | G49: 8 | H49: 0 | I49: 16 | J49: 0 | K49: 0 | L49: 0
A50: Application Tools | B50: Map Tab subtotal | D50: =SUM(D36:D49) | E50: =SUM(E36:E49) | F50: =SUM(F36:F49) | G50: =SUM(G36:G49) | H50: =SUM(H36:H49) | I50: =SUM(I36:I49) | J50: =SUM(J36:J49) | K50: =SUM(K36:K49) | L50: =SUM(L36:L49)
...

Sheet Ribbon Summary
A1: Ribbon area | B1: Total | C1: Dev 1 - Frontend | D1: Dev 2 - Backend | E1: Dev 3 - Design | F1: Dev 3 - .NET | G1: Dev 4 - Testing | H1: PM | I1: CM | J1: PD
A2: Search | B2: ='Integrated ROM'!D10 | C2: ='Integrated ROM'!E10 | D2: ='Integrated ROM'!F10 | E2: ='Integrated ROM'!G10 | F2: ='Integrated ROM'!H10 | G2: ='Integrated ROM'!I10 | H2: ='Integrated ROM'!J10 | I2: ='Integrated ROM'!K10 | J2: ='Integrated ROM'!L10
A3: Home Tab | B3: ='Integrated ROM'!D34 | C3: ='Integrated ROM'!E34 | D3: ='Integrated ROM'!F34 | E3: ='Integrated ROM'!G34 | F3: ='Integrated ROM'!H34 | G3: ='Integrated ROM'!I34 | H3: ='Integrated ROM'!J34 | I3: ='Integrated ROM'!K34 | J3: ='Integrated ROM'!L34
A4: Map Tab | B4: ='Integrated ROM'!D50 | C4: ='Integrated ROM'!E50 | D4: ='Integrated ROM'!F50 | E4: ='Integrated ROM'!G50 | F4: ='Integrated ROM'!H50 | G4: ='Integrated ROM'!I50 | H4: ='Integrated ROM'!J50 | I4: ='Integrated ROM'!K50 | J4: ='Integrated ROM'!L50
A5: Tools Tab | B5: ='Integrated ROM'!D64 | C5: ='Integrated ROM'!E64 | D5: ='Integrated ROM'!F64 | E5: ='Integrated ROM'!G64 | F5: ='Integrated ROM'!H64 | G5: ='Integrated ROM'!I64 | H5: ='Integrated ROM'!J64 | I5: ='Integrated ROM'!K64 | J5: ='Integrated ROM'!L64
A6: Advanced Tools Tab | B6: ='Integrated ROM'!D77 | C6: ='Integrated ROM'!E77 | D6: ='Integrated ROM'!F77 | E6: ='Integrated ROM'!G77 | F6: ='Integrated ROM'!H77 | G6: ='Integrated ROM'!I77 | H6: ='Integrated ROM'!J77 | I6: ='Integrated ROM'!K77 | J6: ='Integrated ROM'!L77
A7: Outside Toolbar | B7: ='Integrated ROM'!D91 | C7: ='Integrated ROM'!E91 | D7: ='Integrated ROM'!F91 | E7: ='Integrated ROM'!G91 | F7: ='Integrated ROM'!H91 | G7: ='Integrated ROM'!I91 | H7: ='Integrated ROM'!J91 | I7: ='Integrated ROM'!K91 | J7: ='Integrated ROM'!L91
A8: Total ribbon/tool effort | B8: =SUM(B2:B7) | C8: =SUM(C2:C7) | D8: =SUM(D2:D7) | E8: =SUM(E2:E7) | F8: =SUM(F2:F7) | G8: =SUM(G2:G7) | H8: =SUM(H2:H7) | I8: =SUM(I2:I7) | J8: =SUM(J2:J7)

Sheet Assumptions
A1: DTP Production Application ROM | B1: Prepared 21 September 2026
A2: Architecture | B2: MapLibre + React frontend, FastAPI spatial API, PostGIS, AWS-hosted services and cached vector tiles.
A3: Estimate type | B3: First-pass person-hour ROM, generally rounded to 8-hour increments, with approximately ±30% uncertainty before requirements validation.
A4: Tool reuse | B4: A capability appearing in multiple ribbon tabs is implemented once. Secondary appearances are estimated as small shared launchers.
A5: PM treatment | B5: The detailed ribbon estimates are preserved from the agreed tables. Tool-level PM is covered by the project governance and delivery-management allowances rather than added to every tool.
A6: Reconciliation | B6: The detailed ribbon estimates replace the former Map controls and application panels, Print and reporting service, Map rendering and symbology, Data catalogue, and VicPlan and Radius business workflows rows to avoid double counting.
A7: Excluded / validate | B7: Third-party licence costs, data remediation at unknown scale, external service procurement, production support beyond warranty, and material scope changes are not included unless explicitly represented.
A8: Contingency | B8: 20% applied to the calculated base estimate. Change this percentage after discovery and risk review.

Sheet Validation
A1: Check | B1: Formula | C1: Expected
A2: Ribbon total | B2: ='Ribbon Summary'!B8 | C2: 3720
A3: Base total | B3: ='Integrated ROM'!D105 | C3: 5828
A4: Contingency | B4: ='Integrated ROM'!D106 | C4: 1166
A5: Grand total | B5: ='Integrated ROM'!D107 | C5: 6994
