Workbook

Sheet Implementation Plan
A1: Project Start Date | B1: 46286 | D1: Production Go-Live Target | E1: 46598 | G1: Client Review Window (days) | H1: 5 | J1: ROM Contingency | K1: 0.2
A2: Change the yellow start date or target date. Task dates recalculate using Monday-Friday workdays and optional dates on the Holidays sheet. | I2: Target Status | J2: =IF(F39<=$E$1,"ON OR BEFORE TARGET","AFTER TARGET") -> ON OR BEFORE TARGET
A4: WBS | B4: Task Name | C4: Effort Hours | D4: Duration (Working Days) | E4: Start | F4: Finish | G4: Predecessor | H4: Resource Names | I4: Outcome / Deliverable | J4: Status | K4: Release
A5: 1 | B5: Production GIS Application Implementation and Migration | C5: =SUM(C6,C9,C14,C18,C23,C28,C33,C41) -> 6994 | D5: =NETWORKDAYS.INTL(E5,F5,1,Holidays!$A$2:$A$100) -> 289 | E5: =MIN(E6:E46) -> 46286 | F5: =MAX(F6:F46) -> 46702 | I5: Usable production release by July 2027; specialist workflows continue afterwards.
A6: 1.1 | B6: Confirm Scope and Priorities | C6: =SUM(C7:C8) -> 240 | D6: =NETWORKDAYS.INTL(E6,F6,1,Holidays!$A$2:$A$100) -> 15 | E6: =MIN(E7:E8) -> 46286 | F6: =MAX(F7:F8) -> 46304 | I6: Summary of confirm scope and priorities activities. | K6: Scope Baseline
A7: 1.1.1 | B7: Confirm required tools, datasets and first production release | C7: 160 | D7: 10 | E7: =IF(G7="",$B$1,WORKDAY.INTL(INDEX($F:$F,MATCH(G7,$A:$A,0)),1,1,Holidays!$A$2:$A$100)) -> 46286 | F7: =IF(D7=0,E7,WORKDAY.INTL(E7,D7-1,1,Holidays!$A$2:$A$100)) -> 46297 | H7: PM, PD, Design, Frontend, Backend | I7: Prioritised production scope, dataset list and documented assumptions. | J7: Not Started | K7: Scope Baseline
A8: 1.1.2 | B8: Approve scope baseline and change-control approach | C8: 80 | D8: =$H$1 -> 5 | E8: =IF(G8="",$B$1,WORKDAY.INTL(INDEX($F:$F,MATCH(G8,$A:$A,0)),1,1,Holidays!$A$2:$A$100)) -> 46300 | F8: =IF(D8=0,E8,WORKDAY.INTL(E8,D8-1,1,Holidays!$A$2:$A$100)) -> 46304 | G8: 1.1.1 | H8: PM, PD | I8: Single client approval gate; subsequent changes are assessed through change control. | J8: Not Started | K8: Scope Baseline
A9: 1.2 | B9: Establish Production Foundation | C9: =SUM(C10:C13) -> 492 | D9: =NETWORKDAYS.INTL(E9,F9,1,Holidays!$A$2:$A$100) -> 51 | E9: =MIN(E10:E13) -> 46307 | F9: =MAX(F10:F13) -> 46378 | I9: Summary of establish production foundation activities. | K9: Foundation
A10: 1.2.1 | B10: Set up environments and automated deployment | C10: 120 | D10: 15 | E10: =IF(G10="",$B$1,WORKDAY.INTL(INDEX($F:$F,MATCH(G10,$A:$A,0)),1,1,Holidays!$A$2:$A$100)) -> 46307 | F10: =IF(D10=0,E10,WORKDAY.INTL(E10,D10-1,1,Holidays!$A$2:$A$100)) -> 46325 | G10: 1.1.2 | H10: Backend, Frontend | I10: Development, test and production environments with repeatable deployment. | J10: Not Started | K10: Foundation
A11: 1.2.2 | B11: Create PostGIS and backend application foundation | C11: 200 | D11: 20 | E11: =IF(G11="",$B$1,WORKDAY.INTL(INDEX($F:$F,MATCH(G11,$A:$A,0)),1,1,Holidays!$A$2:$A$100)) -> 46328 | F11: =IF(D11=0,E11,WORKDAY.INTL(E11,D11-1,1,Holidays!$A$2:$A$100)) -> 46356 | G11: 1.2.1 | H11: Backend, Frontend, Design, PM | I11: Production database and deployable backend application foundation. | J11: Not Started | K11: Foundation
A12: 1.2.3 | B12: Implement authentication, configuration and operations | C12: 172 | D12: 15 | E12: =IF(G12="",$B$1,WORKDAY.INTL(INDEX($F:$F,MATCH(G12,$A:$A,0)),1,1,Holidays!$A$2:$A$100)) -> 46357 | F12: =IF(D12=0,E12,WORKDAY.INTL(E12,D12-1,1,Holidays!$A$2:$A$100)) -> 46377 | G12: 1.2.2 | H12: Backend, Frontend, PM | I12: Authentication, basic authorisation, logging, monitoring, backups and configuration. | J12: Not Started | K12: Foundation
A13: 1.2.4 | B13: Secure production foundation ready | C13: 0 | D13: 0 | E13: =IF(G13="",$B$1,WORKDAY.INTL(INDEX($F:$F,MATCH(G13,$A:$A,0)),1,1,Holidays!$A$2:$A$100)) -> 46378 | F13: =IF(D13=0,E13,WORKDAY.INTL(E13,D13-1,1,Holidays!$A$2:$A$100)) -> 46378 | G13: 1.2.3 | I13: Milestone: a secure, mostly empty application can be deployed reliably. | J13: Not Started | K13: Foundation
A14: 1.3 | B14: Build Data Pipeline and Core API | C14: =SUM(C15:C17) -> 368 | D14: =NETWORKDAYS.INTL(E14,F14,1,Holidays!$A$2:$A$100) -> 41 | E14: =MIN(E15:E17) -> 46379 | F14: =MAX(F15:F17) -> 46441 | I14: Summary of build data pipeline and core api activities. | K14: Data/API Ready
A15: 1.3.1 | B15: Build spatial data loading and publishing pipeline | C15: 128 | D15: 20 | E15: =IF(G15="",$B$1,WORKDAY.INTL(INDEX($F:$F,MATCH(G15,$A:$A,0)),1,1,Holidays!$A$2:$A$100)) -> 46379 | F15: =IF(D15=0,E15,WORKDAY.INTL(E15,D15-1,1,Holidays!$A$2:$A$100)) -> 46409 | G15: 1.2.4 | H15: Backend, PM | I15: Validated data loading into PostGIS, catalogue publication and cached MapLibre tiles. | J15: Not Started | K15: Data/API Ready
A16: 1.3.2 | B16: Build shared spatial API and ArcGIS authoring integration | C16: 240 | D16: 20 | E16: =IF(G16="",$B$1,WORKDAY.INTL(INDEX($F:$F,MATCH(G16,$A:$A,0)),1,1,Holidays!$A$2:$A$100)) -> 46412 | F16: =IF(D16=0,E16,WORKDAY.INTL(E16,D16-1,1,Holidays!$A$2:$A$100)) -> 46440 | G16: 1.3.1 | H16: Backend, Design, .NET | I16: Shared query, search, identify and spatial operations plus configuration authoring support. | J16: Not Started | K16: Data/API Ready
A17: 1.3.3 | B17: Publish initial production datasets | C17: 0 | D17: 0 | E17: =IF(G17="",$B$1,WORKDAY.INTL(INDEX($F:$F,MATCH(G17,$A:$A,0)),1,1,Holidays!$A$2:$A$100)) -> 46441 | F17: =IF(D17=0,E17,WORKDAY.INTL(E17,D17-1,1,Holidays!$A$2:$A$100)) -> 46441 | G17: 1.3.2 | I17: Milestone: representative public and restricted datasets are available end to end. | J17: Not Started | K17: Data/API Ready
A18: 1.4 | B18: Build the Frontend Application Shell | C18: =SUM(C19:C22) -> 216 | D18: =NETWORKDAYS.INTL(E18,F18,1,Holidays!$A$2:$A$100) -> 31 | E18: =MIN(E19:E22) -> 46379 | F18: =MAX(F19:F22) -> 46427 | I18: Summary of build the frontend application shell activities. | K18: Working Application
A19: 1.4.1 | B19: Build MapLibre shell, ribbon, map and empty panels | C19: 136 | D19: 15 | E19: =IF(G19="",$B$1,WORKDAY.INTL(INDEX($F:$F,MATCH(G19,$A:$A,0)),1,1,Holidays!$A$2:$A$100)) -> 46379 | F19: =IF(D19=0,E19,WORKDAY.INTL(E19,D19-1,1,Holidays!$A$2:$A$100)) -> 46402 | G19: 1.2.4 | H19: Frontend, Backend, Design, PM | I19: MapLibre application with Home, Map, Tools and Advanced Tools structure. | J19: Not Started | K19: Working Application
A20: 1.4.2 | B20: Connect login, catalogue, map data and user state | C20: 80 | D20: 10 | E20: =IF(G20="",$B$1,WORKDAY.INTL(INDEX($F:$F,MATCH(G20,$A:$A,0)),1,1,Holidays!$A$2:$A$100)) -> 46405 | F20: =IF(D20=0,E20,WORKDAY.INTL(E20,D20-1,1,Holidays!$A$2:$A$100)) -> 46419 | G20: 1.4.1 | H20: Frontend | I20: Authenticated working map connected to published data and shared services. | J20: Not Started | K20: Working Application
A21: 1.4.3 | B21: Verify deployable working application | C21: 0 | D21: 5 | E21: =IF(G21="",$B$1,WORKDAY.INTL(INDEX($F:$F,MATCH(G21,$A:$A,0)),1,1,Holidays!$A$2:$A$100)) -> 46420 | F21: =IF(D21=0,E21,WORKDAY.INTL(E21,D21-1,1,Holidays!$A$2:$A$100)) -> 46426 | G21: 1.4.2 | H21: Frontend, Backend, Testing | I21: Working application in each environment, ready for incremental tools. | J21: Not Started | K21: Working Application
A22: 1.4.4 | B22: Frontend foundation ready | C22: 0 | D22: 0 | E22: =IF(G22="",$B$1,WORKDAY.INTL(INDEX($F:$F,MATCH(G22,$A:$A,0)),1,1,Holidays!$A$2:$A$100)) -> 46427 | F22: =IF(D22=0,E22,WORKDAY.INTL(E22,D22-1,1,Holidays!$A$2:$A$100)) -> 46427 | G22: 1.4.3 | I22: Milestone: working application foundation available early in delivery. | J22: Not Started | K22: Working Application
A23: 1.5 | B23: Deliver Core Map Tools | C23: =SUM(C24:C27) -> 1120 | D23: =NETWORKDAYS.INTL(E23,F23,1,Holidays!$A$2:$A$100) -> 51 | E23: =MIN(E24:E27) -> 46442 | F23: =MAX(F24:F27) -> 46518 | I23: Summary of deliver core map tools activities. | K23: Core Toolset
A24: 1.5.1 | B24: Search, layer catalogue, layer list and map navigation | C24: 560 | D24: 20 | E24: =IF(G24="",$B$1,WORKDAY.INTL(INDEX($F:$F,MATCH(G24,$A:$A,0)),1,1,Holidays!$A$2:$A$100)) -> 46442 | F24: =IF(D24=0,E24,WORKDAY.INTL(E24,D24-1,1,Holidays!$A$2:$A$100)) -> 46470 | G24: 1.3.3 | H24: Frontend, Backend, Design, Testing | I24: Users can locate an area and manage authorised map layers. | J24: Not Started | K24: Core Toolset
A25: 1.5.2 | B25: Identify, query, table view, metadata and filtering | C25: 560 | D25: 25 | E25: =IF(G25="",$B$1,WORKDAY.INTL(INDEX($F:$F,MATCH(G25,$A:$A,0)),1,1,Holidays!$A$2:$A$100)) -> 46471 | F25: =IF(D25=0,E25,WORKDAY.INTL(E25,D25-1,1,Holidays!$A$2:$A$100)) -> 46510 | G25: 1.5.1 | H25: Frontend, Backend, Design, Testing | I25: Users can inspect, query, filter and work with map features and attributes. | J25: Not Started | K25: Core Toolset
A26: 1.5.3 | B26: Core tools demonstration and acceptance window | C26: 0 | D26: =$H$1 -> 5 | E26: =IF(G26="",$B$1,WORKDAY.INTL(INDEX($F:$F,MATCH(G26,$A:$A,0)),1,1,Holidays!$A$2:$A$100)) -> 46511 | F26: =IF(D26=0,E26,WORKDAY.INTL(E26,D26-1,1,Holidays!$A$2:$A$100)) -> 46517 | G26: 1.5.2 | H26: PM, PD | I26: First meaningful consolidated client review and acceptance point. | J26: Not Started | K26: Core Toolset
A27: 1.5.4 | B27: Core map tools production-ready | C27: 0 | D27: 0 | E27: =IF(G27="",$B$1,WORKDAY.INTL(INDEX($F:$F,MATCH(G27,$A:$A,0)),1,1,Holidays!$A$2:$A$100)) -> 46518 | F27: =IF(D27=0,E27,WORKDAY.INTL(E27,D27-1,1,Holidays!$A$2:$A$100)) -> 46518 | G27: 1.5.3 | I27: Milestone: essential map workflow is ready for release. | J27: Not Started | K27: Core Toolset
A28: 1.6 | B28: Deliver General GIS Tools | C28: =SUM(C29:C32) -> 1680 | D28: =NETWORKDAYS.INTL(E28,F28,1,Holidays!$A$2:$A$100) -> 35 | E28: =MIN(E29:E32) -> 46519 | F28: =MAX(F29:F32) -> 46568 | I28: Summary of deliver general gis tools activities. | K28: Main Toolset
A29: 1.6.1 | B29: Measurement, drawing and editing | C29: 400 | D29: 10 | E29: =IF(G29="",$B$1,WORKDAY.INTL(INDEX($F:$F,MATCH(G29,$A:$A,0)),1,1,Holidays!$A$2:$A$100)) -> 46519 | F29: =IF(D29=0,E29,WORKDAY.INTL(E29,D29-1,1,Holidays!$A$2:$A$100)) -> 46532 | G29: 1.5.4 | H29: Frontend, Backend, Design, Testing | I29: Measurement and reusable drawing/editing capability. | J29: Not Started | K29: Main Toolset
A30: 1.6.2 | B30: Buffering, intersects, filters and property calculations | C30: 520 | D30: 12 | E30: =IF(G30="",$B$1,WORKDAY.INTL(INDEX($F:$F,MATCH(G30,$A:$A,0)),1,1,Holidays!$A$2:$A$100)) -> 46533 | F30: =IF(D30=0,E30,WORKDAY.INTL(E30,D30-1,1,Holidays!$A$2:$A$100)) -> 46548 | G30: 1.6.1 | H30: Frontend, Backend, Testing | I30: General spatial analysis used by VicPlan and Radius workflows. | J30: Not Started | K30: Main Toolset
A31: 1.6.3 | B31: Projects, sharing, upload, export and printing | C31: 760 | D31: 12 | E31: =IF(G31="",$B$1,WORKDAY.INTL(INDEX($F:$F,MATCH(G31,$A:$A,0)),1,1,Holidays!$A$2:$A$100)) -> 46549 | F31: =IF(D31=0,E31,WORKDAY.INTL(E31,D31-1,1,Holidays!$A$2:$A$100)) -> 46567 | G31: 1.6.2 | H31: Frontend, Backend, Design, Testing | I31: Saved work, secure data exchange and production map outputs. | J31: Not Started | K31: Main Toolset
A32: 1.6.4 | B32: Main production toolset complete | C32: 0 | D32: 0 | E32: =IF(G32="",$B$1,WORKDAY.INTL(INDEX($F:$F,MATCH(G32,$A:$A,0)),1,1,Holidays!$A$2:$A$100)) -> 46568 | F32: =IF(D32=0,E32,WORKDAY.INTL(E32,D32-1,1,Holidays!$A$2:$A$100)) -> 46568 | G32: 1.6.3 | I32: Milestone: main tools are available before migration and launch. | J32: Not Started | K32: Main Toolset
A33: 1.7 | B33: Migration, Acceptance and Launch | C33: =SUM(C34:C40) -> 1958 | D33: =NETWORKDAYS.INTL(E33,F33,1,Holidays!$A$2:$A$100) -> 67 | E33: =MIN(E34:E40) -> 46519 | F33: =MAX(F34:F40) -> 46612 | I33: Summary of migration, acceptance and launch activities. | K33: July 2027 Production
A34: 1.7.1 | B34: Prepare documentation and operational handover | C34: 200 | D34: 15 | E34: =IF(G34="",$B$1,WORKDAY.INTL(INDEX($F:$F,MATCH(G34,$A:$A,0)),1,1,Holidays!$A$2:$A$100)) -> 46519 | F34: =IF(D34=0,E34,WORKDAY.INTL(E34,D34-1,1,Holidays!$A$2:$A$100)) -> 46539 | G34: 1.5.4 | H34: Frontend, Backend, .NET, PM | I34: User, administrator, support and technical material prepared in parallel with tool delivery. | J34: Not Started | K34: July 2027 Production
A35: 1.7.2 | B35: Production hardening, regression and migration rehearsal | C35: 352 | D35: 10 | E35: =IF(G35="",$B$1,WORKDAY.INTL(INDEX($F:$F,MATCH(G35,$A:$A,0)),1,1,Holidays!$A$2:$A$100)) -> 46569 | F35: =IF(D35=0,E35,WORKDAY.INTL(E35,D35-1,1,Holidays!$A$2:$A$100)) -> 46582 | G35: 1.6.4 | H35: Frontend, Backend, Testing | I35: Performance, security, accessibility, regression and final data/configuration rehearsal. | J35: Not Started | K35: July 2027 Production
A36: 1.7.3 | B36: Consolidated UAT, training and final migration | C36: 80 | D36: 9 | E36: =IF(G36="",$B$1,WORKDAY.INTL(INDEX($F:$F,MATCH(G36,$A:$A,0)),1,1,Holidays!$A$2:$A$100)) -> 46583 | F36: =IF(D36=0,E36,WORKDAY.INTL(E36,D36-1,1,Holidays!$A$2:$A$100)) -> 46595 | G36: 1.7.2 | H36: Frontend, Backend, Testing, PM, PD | I36: Business acceptance, trained users/support staff and production data ready for cutover. | J36: Not Started | K36: July 2027 Production
A37: 1.7.4 | B37: Delivery contingency and remediation allowance | C37: =ROUND(SUM(C7,C8,C10,C11,C12,C13,C15,C16,C17,C19,C20,C21,C22,C24,C25,C26,C27,C29,C30,C31,C32,C34,C35,C36,C38,C39,C40,C42,C43,C44,C45,C46)*$K$1,0) -> 1166 | D37: 0 | E37: =IF(G37="",$B$1,WORKDAY.INTL(INDEX($F:$F,MATCH(G37,$A:$A,0)),1,1,Holidays!$A$2:$A$100)) -> 46596 | F37: =IF(D37=0,E37,WORKDAY.INTL(E37,D37-1,1,Holidays!$A$2:$A$100)) -> 46596 | G37: 1.7.3 | H37: Frontend, Backend, Design, .NET, Testing, PM, PD | I37: Budget contingency retained in the ROM; no separate delay is forced into the baseline schedule. Any use of contingency is managed through delivery forecasts. | J37: Not Started | K37: July 2027 Production
A38: 1.7.5 | B38: Environment promotion and production cutover | C38: 80 | D38: 1 | E38: =IF(G38="",$B$1,WORKDAY.INTL(INDEX($F:$F,MATCH(G38,$A:$A,0)),1,1,Holidays!$A$2:$A$100)) -> 46597 | F38: =IF(D38=0,E38,WORKDAY.INTL(E38,D38-1,1,Holidays!$A$2:$A$100)) -> 46597 | G38: 1.7.4 | H38: Frontend, Backend | I38: Deploy, migrate, verify and switch the supported production service. | J38: Not Started | K38: July 2027 Production
A39: 1.7.6 | B39: Production Go Live | C39: 0 | D39: 0 | E39: =IF(G39="",$B$1,WORKDAY.INTL(INDEX($F:$F,MATCH(G39,$A:$A,0)),1,1,Holidays!$A$2:$A$100)) -> 46598 | F39: =IF(D39=0,E39,WORKDAY.INTL(E39,D39-1,1,Holidays!$A$2:$A$100)) -> 46598 | G39: 1.7.5 | I39: Milestone: usable application, main tools and migration complete by the July 2027 target. | J39: Not Started | K39: July 2027 Production
A40: 1.7.7 | B40: Warranty and hypercare | C40: 80 | D40: 10 | E40: =IF(G40="",$B$1,WORKDAY.INTL(INDEX($F:$F,MATCH(G40,$A:$A,0)),1,1,Holidays!$A$2:$A$100)) -> 46601 | F40: =IF(D40=0,E40,WORKDAY.INTL(E40,D40-1,1,Holidays!$A$2:$A$100)) -> 46612 | G40: 1.7.6 | H40: Frontend, Backend | I40: Post-launch monitoring and prioritised remediation. | J40: Not Started | K40: July 2027 Production
A41: 1.8 | B41: Deliver Specialist Workflows After Launch | C41: =SUM(C42:C46) -> 920 | D41: =NETWORKDAYS.INTL(E41,F41,1,Holidays!$A$2:$A$100) -> 64 | E41: =MIN(E42:E46) -> 46615 | F41: =MAX(F42:F46) -> 46702 | I41: Summary of deliver specialist workflows after launch activities. | K41: Post-Launch Enhancements
...

Sheet Holidays
A1: Excluded Work Date | B1: Description
A2: 46329 | B2: Melbourne Cup Day
A3: 46381 | B3: Christmas Day
A4: 46384 | B4: Boxing Day substitute
A5: 46388 | B5: New Year's Day
A6: 46413 | B6: Australia Day
A7: 46454 | B7: Labour Day
A8: 46472 | B8: Good Friday
A9: 46475 | B9: Easter Monday
A10: 46503 | B10: ANZAC Day substitute
A11: 46552 | B11: King's Birthday

Sheet Plan Notes
A1: Topic | B1: Detail
A2: Delivery objective | B2: A usable migrated production application containing the core and general GIS tools is targeted for July 2027.
A3: Map technology | B3: The production map client is MapLibre.
A4: Working foundation | B4: The secure platform, data path and empty application shell are delivered early so the application remains deployable throughout development.
A5: Pre-launch tools | B5: Search, catalogue, layer management, identify, query, table, navigation, metadata/filtering, measurement, drawing, spatial analysis, projects, upload/export and printing are scheduled before Go Live.
A6: Post-launch tools | B6: Planning/heritage workflows, advanced summaries, imagery search, time slider and Street View are scheduled after Go Live and released incrementally.
A7: Client feedback | B7: Feedback is batched into scope approval, core-tool acceptance and consolidated UAT rather than requested for every tool.
A8: Small-team model | B8: The plan is mostly sequential, with only the data/API and frontend foundations overlapping where the backend and frontend developers can work independently.
A9: Estimate alignment | B9: Base estimate is 5,828 hours. The editable 20% contingency is 1,166 hours, producing 6,994 hours.
A10: Scheduling | B10: Change the yellow Project Start Date. Predecessors, weekdays and the Holidays sheet drive all dates.

Sheet Validation
A1: Check | B1: Formula | C1: Expected
A2: Total effort | B2: ='Implementation Plan'!C5 -> 6994 | C2: 6994
A3: Base effort | B3: =B2-1166 -> 5828 | C3: 5828
A4: Go Live target | B4: ='Implementation Plan'!F39 -> 46598 | C4: 46598
